<sdf version='1.6'>
  <world name='default'>
    <gravity>0 0 -9.8</gravity>
    <magnetic_field>6e-06 2.3e-05 -4.2e-05</magnetic_field>
    <atmosphere type='adiabatic'/>
    <physics name='default_physics' default='0' type='ode'>
      <max_contacts>5</max_contacts>
      <ode>
        <solver>
          <type>quick</type>
          <iters>50</iters>
          <precon_iters>0</precon_iters>
          <sor>1.3</sor>
          <use_dynamic_moi_rescaling>0</use_dynamic_moi_rescaling>
        </solver>
        <constraints>
          <cfm>0</cfm>
          <erp>0.2</erp>
          <contact_max_correcting_vel>100</contact_max_correcting_vel>
          <contact_surface_layer>0.001</contact_surface_layer>
        </constraints>
      </ode>
      <max_step_size>0.001</max_step_size>
      <real_time_factor>1</real_time_factor>
      <real_time_update_rate>1000</real_time_update_rate>
    </physics>
    <scene>
      <ambient>0.4 0.4 0.4 1</ambient>
      <background>0.7 0.7 1 1</background>
      <shadows>1</shadows>
    </scene>
    <spherical_coordinates>
      <surface_model>EARTH_WGS84</surface_model>
      <latitude_deg>0</latitude_deg>
      <longitude_deg>0</longitude_deg>
      <elevation>0</elevation>
      <heading_deg>0</heading_deg>
    </spherical_coordinates>
    <model name='cafe_table'>
      <static>1</static>
      <link name='link'>
        <collision name='surface'>
          <pose frame=''>0 0 0.755 0 -0 0</pose>
          <geometry>
            <box>
              <size>0.913 0.913 0.04</size>
            </box>
          </geometry>
          <max_contacts>10</max_contacts>
          <surface>
            <contact>
              <ode/>
            </contact>
            <bounce/>
            <friction>
              <torsional>
                <ode/>
              </torsional>
              <ode/>
            </friction>
          </surface>
        </collision>
        <collision name='column'>
          <pose frame=''>0 0 0.37 0 -0 0</pose>
          <geometry>
            <box>
              <size>0.042 0.042 0.74</size>
            </box>
          </geometry>
          <max_contacts>10</max_contacts>
          <surface>
            <contact>
              <ode/>
            </contact>
            <bounce/>
            <friction>
              <torsional>
                <ode/>
              </torsional>
              <ode/>
            </friction>
          </surface>
        </collision>
        <collision name='base'>
          <pose frame=''>0 0 0.02 0 -0 0</pose>
          <geometry>
            <box>
              <size>0.56 0.56 0.04</size>
            </box>
          </geometry>
          <max_contacts>10</max_contacts>
          <surface>
            <contact>
              <ode/>
            </contact>
            <bounce/>
            <friction>
              <torsional>
                <ode/>
              </torsional>
              <ode/>
            </friction>
          </surface>
        </collision>
        <visual name='visual'>
          <geometry>
            <mesh>
              <uri>model://cafe_table/meshes/cafe_table.dae</uri>
              <scale>1 1 1</scale>
            </mesh>
          </geometry>
        </visual>
        <self_collide>0</self_collide>
        <kinematic>0</kinematic>
        <enable_wind>0</enable_wind>
      </link>
      <pose frame=''>-0.168004 0.136981 0 0 -0 0</pose>
    </model>
    <light name='user_spot_light_0' type='spot'>
      <pose frame=''>-0.614545 -0.753038 2.0714 0.392405 -0 0</pose>
      <diffuse>0.7 0.5 0.2 1</diffuse>
      <specular>0.1 0.1 0.1 1</specular>
      <direction>0 0 -1</direction>
      <attenuation>
        <range>20</range>
        <constant>0.5</constant>
        <linear>0.01</linear>
        <quadratic>0.001</quadratic>
      </attenuation>
      <cast_shadows>0</cast_shadows>
      <spot>
        <inner_angle>0.6</inner_angle>
        <outer_angle>1</outer_angle>
        <falloff>1</falloff>
      </spot>
    </light>
    <state world_name='default'>
      <sim_time>35 140000000</sim_time>
      <real_time>36 325639899</real_time>
      <wall_time>1613838235 270577424</wall_time>
      <iterations>35140</iterations>
      <model name='cafe_table'>
        <pose frame=''>-0.168004 0.136981 0 0 -0 0</pose>
        <scale>1 1 1</scale>
        <link name='link'>
          <pose frame=''>-0.168004 0.136981 0 0 -0 0</pose>
          <velocity>0 0 0 0 -0 0</velocity>
          <acceleration>0 0 0 0 -0 0</acceleration>
          <wrench>0 0 0 0 -0 0</wrench>
        </link>
      </model>
      <model name='coke_can'>
        <pose frame=''>0.0 0.0 1.0 -0.05413 -0.011413 -0.000724</pose>
        <scale>1 1 1</scale>
        <link name='link'>
          <pose frame=''>0.0 0.0 1.0 -0.05413 -0.011413 -0.000724</pose>
          <velocity>0 0 0 0 -0 0</velocity>
          <acceleration>-0.004399 -0.011865 -0.000106 0.205458 -0.076609 -0.002433</acceleration>
          <wrench>-0.001716 -0.004627 -4.1e-05 0 -0 0</wrench>
        </link>
      </model>
      <model name='ground_plane'>
        <pose frame=''>0.343524 0.647311 0 0 -0 0</pose>
        <scale>1 1 1</scale>
        <link name='link'>
          <pose frame=''>0.343524 0.647311 0 0 -0 0</pose>
          <velocity>0 0 0 0 -0 0</velocity>
          <acceleration>0 0 0 0 -0 0</acceleration>
          <wrench>0 0 0 0 -0 0</wrench>
        </link>
      </model>
      <model name='smart_grasping_sandbox'>
        <pose frame=''>0.000248 6.2e-05 6.3e-05 6.2e-05 -0.000248 0</pose>
        <scale>1 1 1</scale>
        <link name='H1_F1_base_link'>
          <pose frame=''>1.22787 -0.733312 0.972697 -1.57109 -0.06561 -0.00086</pose>
          <velocity>-0.005149 -0.000259 -0.039091 9.7e-05 0.288913 -0.000105</velocity>
          <acceleration>-0.212007 0.032448 0.038323 0.190257 -1.12206 2.31381</acceleration>
          <wrench>-0.037027 0.005667 0.006693 0 -0 0</wrench>
        </link>
        <link name='H1_F1_link_1'>
          <pose frame=''>1.23027 -0.616494 0.937739 -2.89669 -0.065611 -0.00086</pose>
          <velocity>-0.015237 -0.000268 -0.039772 0.012014 0.288905 0.000677</velocity>
          <acceleration>-0.483236 -0.032549 0.016716 0.56213 1.46435 2.22669</acceleration>
          <wrench>-0.04 -0.002694 0.001384 0 -0 0</wrench>
        </link>
        <link name='H1_F1_link_2'>
          <pose frame=''>1.2341 -0.601949 0.879655 3.00599 -0.06561 -0.00086</pose>
          <velocity>-0.032028 0.000437 -0.040705 -0.128855 0.289025 -0.008606</velocity>
          <acceleration>-0.886741 0.156494 -0.038331 0.625484 1.42848 0.318415</acceleration>
          <wrench>-0.031983 0.005644 -0.001383 0 -0 0</wrench>
        </link>
        <link name='H1_F2_base_link'>
          <pose frame=''>1.18348 -0.733258 1.02819 1.5711 -0.392631 3.1406</pose>
          <velocity>-0.003269 -0.000254 -0.037581 2.3e-05 0.033058 -1.5e-05</velocity>
          <acceleration>0.130298 0.005226 -0.015725 -2.00306 0.653112 0.333905</acceleration>
          <wrench>0.022757 0.000913 -0.002746 0 -0 0</wrench>
        </link>
        <link name='H1_F2_link_1'>
          <pose frame=''>1.19697 -0.616431 1.0605 2.68899 -0.392627 3.14061</pose>
          <velocity>-0.002199 -0.000255 -0.038024 2.6e-05 0.033083 6e-06</velocity>
          <acceleration>0.041503 0.009678 0.035852 -0.476147 0.113548 -1.7074</acceleration>
          <wrench>0.003435 0.000801 0.002968 0 -0 0</wrench>
        </link>
        <link name='H1_F2_link_2'>
          <pose frame=''>1.17636 -0.590175 1.01064 -2.77158 -0.392628 3.1406</pose>
          <velocity>-0.003922 -0.000363 -0.037518 1.53828 0.037652 1.96481</velocity>
          <acceleration>-0.358056 2.11726 -0.244707 2.59494 -1.20264 1.6715</acceleration>
          <wrench>-0.012914 0.076366 -0.008826 0 -0 0</wrench>
        </link>
        <link name='H1_F3_base_link'>
          <pose frame=''>1.13788 -0.733233 0.973695 -1.57105 0.092889 -0.000901</pose>
          <velocity>-0.005114 -0.000252 -0.036036 1.9e-05 0.064887 -3.1e-05</velocity>
          <acceleration>0.19219 0.024243 0.019436 2.51752 -1.33425 -2.178</acceleration>
          <wrench>0.033566 0.004234 0.003394 0 -0 0</wrench>
        </link>
        <link name='H1_F3_link_1'>
          <pose frame=''>1.13473 -0.616409 0.938813 -2.89662 0.092889 -0.000902</pose>
          <velocity>-0.007374 -0.00025 -0.035828 2.9e-05 0.064885 -3e-05</velocity>
          <acceleration>0.450051 0.032362 0.010088 0.258693 -1.43636 1.45073</acceleration>
          <wrench>0.037253 0.002679 0.000835 0 -0 0</wrench>
        </link>
        <link name='base_link'>
          <pose frame=''>0 -1 1 6.2e-05 -0.000248 0</pose>
          <velocity>0 0 0 1e-05 7e-06 0</velocity>
          <acceleration>-1.7e-05 0.000109 0.000136 -0.006651 -0.002842 -0.0008</acceleration>
          <wrench>-6.9e-05 0.000435 0.000546 0 -0 0</wrench>
        </link>
        <link name='forearm_link'>
          <pose frame=''>0.611978 -0.951503 1.12095 -3.12541 1.56027 -3.12628</pose>
          <velocity>-0.000189 -0.000132 -0.01925 -2e-06 0.032083 -0.000213</velocity>
          <acceleration>0.000689 -0.00057 -0.005839 0.132819 0.007456 -0.001048</acceleration>
          <wrench>0.002668 -0.002204 -0.022596 0 -0 0</wrench>
        </link>
        <link name='shoulder_link'>
          <pose frame=''>-3.2e-05 -1.00001 1.1273 -0.000132 0.00053 -0.000872</pose>
          <velocity>0 -2e-06 -0 -1.9e-05 -1.7e-05 -0.000208</velocity>
          <acceleration>0.00028 -0.003245 -0.000246 0.025169 0.007797 0.001229</acceleration>
          <wrench>0.00218 -0.025242 -0.001915 0 -0 0</wrench>
        </link>
        <link name='smart_grasping_sandbox::smart_grasping_sandbox::H1_F3_link_2'>
          <pose frame=''>1.12935 -0.601848 0.880855 2.96781 0.09289 -0.000902</pose>
          <velocity>-0.011135 -0.000248 -0.035492 1.10224 0.063886 -0.102683</velocity>
          <acceleration>0.837357 0.433365 -0.027661 3.11239 -1.51877 0.967032</acceleration>
          <wrench>0.030202 0.015631 -0.000998 0 -0 0</wrench>
        </link>
        <link name='upper_arm_link'>
          <pose frame=''>0.00016 -0.779068 1.12725 -3.12318 1.56045 -3.12405</pose>
          <velocity>4.6e-05 -2e-06 -5e-06 0 0.031457 -0.000212</velocity>
          <acceleration>0.000341 -0.002623 2e-05 0.19632 0.007663 -0.001672</acceleration>
          <wrench>0.004408 -0.033919 0.000255 0 -0 0</wrench>
        </link>
        <link name='wrist_1_link'>
          <pose frame=''>1.18425 -0.952003 1.11493 -3.14141 -0.011018 3.14072</pose>
          <velocity>-0.000382 -0.000254 -0.03761 -1e-06 0.033649 -0.000214</velocity>
          <acceleration>0.000681 0.000376 -0.007395 0.02766 0.004153 0.000821</acceleration>
          <wrench>0.001334 0.000737 -0.014494 0 -0 0</wrench>
        </link>
        <link name='wrist_2_link'>
          <pose frame=''>1.18435 -0.837103 1.1149 -3.14135 -0.011019 3.14071</pose>
          <velocity>-0.000359 -0.000254 -0.037612 6e-06 0.033652 -2.2e-05</velocity>
          <acceleration>0.000265 0.000501 -0.001148 0.106562 0.00616 0.007476</acceleration>
          <wrench>0.000519 0.000982 -0.002249 0 -0 0</wrench>
        </link>
        <link name='wrist_3_link'>
          <pose frame=''>1.18307 -0.83713 0.999206 -3.14134 -0.011081 3.14071</pose>
          <velocity>-0.004252 -0.000254 -0.03757 -3e-06 0.03387 -2.2e-05</velocity>
          <acceleration>-0.002456 0.01506 0.016788 0.217481 -0.115773 0.580575</acceleration>
          <wrench>-0.000933 0.005718 0.006375 0 -0 0</wrench>
        </link>
      </model>
      <light name='user_directional_light_0'>
        <pose frame=''>0 0 3 0 -0 0</pose>
      </light>
      <light name='user_directional_light_2'>
        <pose frame=''>0.731132 -0.890069 1 0 -0 0</pose>
      </light>
      <light name='user_spot_light_0'>
        <pose frame=''>-0.614545 -0.753038 2.0714 0.392405 -0 0</pose>
      </light>
    </state>
    <gui fullscreen='0'>
      <camera name='user_camera'>
        <pose frame=''>-4.5649 -1.70172 3.83751 0 0.547644 0.304983</pose>
        <view_controller>orbit</view_controller>
        <projection_type>perspective</projection_type>
      </camera>
    </gui>
    <light name='user_directional_light_0' type='directional'>
      <pose frame=''>0 0 3 0 -0 0</pose>
      <diffuse>0.9 0.85 0.8 1</diffuse>
      <specular>0.1 0.1 0.1 1</specular>
      <direction>0.1 0.1 -0.9</direction>
      <attenuation>
        <range>20</range>
        <constant>0.5</constant>
        <linear>0.01</linear>
        <quadratic>0.001</quadratic>
      </attenuation>
      <cast_shadows>1</cast_shadows>
    </light>
    <audio>
      <device>default</device>
    </audio>
    <wind/>
    <model name='smart_grasping_sandbox'>
      <link name='base_link'>
        <pose frame=''>0 -1 1 0 -0 0</pose>
        <inertial>
          <pose frame=''>0 0 0 0 -0 0</pose>
          <mass>4</mass>
          <inertia>
            <ixx>0.00610633</ixx>
            <ixy>0</ixy>
            <ixz>0</ixz>
            <iyy>0.00610633</iyy>
            <iyz>0</iyz>
            <izz>0.01125</izz>
          </inertia>
        </inertial>
        <collision name='base_link_collision'>
          <pose frame=''>0 0 0 0 -0 0</pose>
          <geometry>
            <mesh>
              <scale>1 1 1</scale>
              <uri>/home/gizem/catkin_ws/src/fmauch_universal_robot/ur_description/meshes/ur10/collision/base.stl</uri>
            </mesh>
          </geometry>
          <max_contacts>10</max_contacts>
          <surface>
            <contact>
              <ode/>
            </contact>
            <bounce/>
            <friction>
              <torsional>
                <ode/>
              </torsional>
              <ode/>
            </friction>
          </surface>
        </collision>
        <visual name='base_link_visual'>
          <pose frame=''>0 0 0 0 -0 0</pose>
          <geometry>
            <mesh>
              <scale>1 1 1</scale>
              <uri>/home/gizem/catkin_ws/src/fmauch_universal_robot/ur_description/meshes/ur10/visual/base.dae</uri>
            </mesh>
          </geometry>
        </visual>
        <self_collide>0</self_collide>
        <enable_wind>0</enable_wind>
        <kinematic>0</kinematic>
      </link>
      <joint name='world_joint' type='fixed'>
        <child>base_link</child>
        <parent>world</parent>
      </joint>
      <link name='shoulder_link'>
        <pose frame=''>0 -1 1.1273 0 -0 0</pose>
        <inertial>
          <pose frame=''>0 0 0 0 -0 0</pose>
          <mass>7.778</mass>
          <inertia>
            <ixx>0.0314743</ixx>
            <ixy>0</ixy>
            <ixz>0</ixz>
            <iyy>0.0314743</iyy>
            <iyz>0</iyz>
            <izz>0.0218756</izz>
          </inertia>
        </inertial>
        <collision name='shoulder_link_collision'>
          <pose frame=''>0 0 0 0 -0 0</pose>
          <geometry>
            <mesh>
              <scale>1 1 1</scale>
              <uri>/home/gizem/catkin_ws/src/fmauch_universal_robot/ur_description/meshes/ur10/collision/shoulder.stl</uri>
            </mesh>
          </geometry>
          <max_contacts>10</max_contacts>
          <surface>
            <contact>
              <ode/>
            </contact>
            <bounce/>
            <friction>
              <torsional>
                <ode/>
              </torsional>
              <ode/>
            </friction>
          </surface>
        </collision>
        <visual name='shoulder_link_visual'>
          <pose frame=''>0 0 0 0 -0 0</pose>
          <geometry>
            <mesh>
              <scale>1 1 1</scale>
              <uri>/home/gizem/catkin_ws/src/fmauch_universal_robot/ur_description/meshes/ur10/visual/shoulder.dae</uri>
            </mesh>
          </geometry>
        </visual>
        <self_collide>0</self_collide>
        <enable_wind>0</enable_wind>
        <kinematic>0</kinematic>
      </link>
      <joint name='shoulder_pan_joint' type='revolute'>
        <child>shoulder_link</child>
        <parent>base_link</parent>
        <axis>
          <xyz>0 0 1</xyz>
          <limit>
            <lower>-3.14159</lower>
            <upper>3.14159</upper>
            <effort>330</effort>
            <velocity>2.16</velocity>
          </limit>
          <dynamics>
            <damping>0</damping>
            <friction>0</friction>
            <spring_reference>0</spring_reference>
            <spring_stiffness>0</spring_stiffness>
          </dynamics>
          <use_parent_model_frame>1</use_parent_model_frame>
        </axis>
      </joint>
      <link name='upper_arm_link'>
        <pose frame=''>0 -0.779059 1.1273 3.14159 1.57079 3.14159</pose>
        <inertial>
          <pose frame=''>0 0 0.306 0 -0 0</pose>
          <mass>12.93</mass>
          <inertia>
            <ixx>0.421754</ixx>
            <ixy>0</ixy>
            <ixz>0</ixz>
            <iyy>0.421754</iyy>
            <iyz>0</iyz>
            <izz>0.0363656</izz>
          </inertia>
        </inertial>
        <collision name='upper_arm_link_collision'>
          <pose frame=''>0 0 0 0 -0 0</pose>
          <geometry>
            <mesh>
              <scale>1 1 1</scale>
              <uri>/home/gizem/catkin_ws/src/fmauch_universal_robot/ur_description/meshes/ur10/collision/upperarm.stl</uri>
            </mesh>
          </geometry>
          <max_contacts>10</max_contacts>
          <surface>
            <contact>
              <ode/>
            </contact>
            <bounce/>
            <friction>
              <torsional>
                <ode/>
              </torsional>
              <ode/>
            </friction>
          </surface>
        </collision>
        <visual name='upper_arm_link_visual'>
          <pose frame=''>0 0 0 0 -0 0</pose>
          <geometry>
            <mesh>
              <scale>1 1 1</scale>
              <uri>/home/gizem/catkin_ws/src/fmauch_universal_robot/ur_description/meshes/ur10/visual/upperarm.dae</uri>
            </mesh>
          </geometry>
        </visual>
        <self_collide>0</self_collide>
        <enable_wind>0</enable_wind>
        <kinematic>0</kinematic>
      </link>
      <joint name='shoulder_lift_joint' type='revolute'>
        <child>upper_arm_link</child>
        <parent>shoulder_link</parent>
        <axis>
          <xyz>0 1 0</xyz>
          <limit>
            <lower>-3.14159</lower>
            <upper>3.14159</upper>
            <effort>330</effort>
            <velocity>2.16</velocity>
          </limit>
          <dynamics>
            <damping>0</damping>
            <friction>0</friction>
            <spring_reference>0</spring_reference>
            <spring_stiffness>0</spring_stiffness>
          </dynamics>
          <use_parent_model_frame>1</use_parent_model_frame>
        </axis>
      </joint>
      <link name='forearm_link'>
        <pose frame=''>0.612 -0.950959 1.1273 3.14159 1.57079 3.14159</pose>
        <inertial>
          <pose frame=''>0 0 0.28615 0 -0 0</pose>
          <mass>3.87</mass>
          <inertia>
            <ixx>0.11107</ixx>
            <ixy>0</ixy>
            <ixz>0</ixz>
            <iyy>0.11107</iyy>
            <iyz>0</iyz>
            <izz>0.0108844</izz>
          </inertia>
        </inertial>
        <collision name='forearm_link_collision'>
          <pose frame=''>0 0 0 0 -0 0</pose>
          <geometry>
            <mesh>
              <scale>1 1 1</scale>
              <uri>/home/gizem/catkin_ws/src/fmauch_universal_robot/ur_description/meshes/ur10/collision/forearm.stl</uri>
            </mesh>
          </geometry>
          <max_contacts>10</max_contacts>
          <surface>
            <contact>
              <ode/>
            </contact>
            <bounce/>
            <friction>
              <torsional>
                <ode/>
              </torsional>
              <ode/>
            </friction>
          </surface>
        </collision>
        <visual name='forearm_link_visual'>
          <pose frame=''>0 0 0 0 -0 0</pose>
          <geometry>
            <mesh>
              <scale>1 1 1</scale>
              <uri>/home/gizem/catkin_ws/src/fmauch_universal_robot/ur_description/meshes/ur10/visual/forearm.dae</uri>
            </mesh>
          </geometry>
        </visual>
        <self_collide>0</self_collide>
        <enable_wind>0</enable_wind>
        <kinematic>0</kinematic>
      </link>
      <joint name='elbow_joint' type='revolute'>
        <child>forearm_link</child>
        <parent>upper_arm_link</parent>
        <axis>
          <xyz>0 1 0</xyz>
          <limit>
            <lower>-3.14159</lower>
            <upper>3.14159</upper>
            <effort>150</effort>
            <velocity>3.15</velocity>
          </limit>
          <dynamics>
            <damping>0</damping>
            <friction>0</friction>
            <spring_reference>0</spring_reference>
            <spring_stiffness>0</spring_stiffness>
          </dynamics>
          <use_parent_model_frame>1</use_parent_model_frame>
        </axis>
      </joint>
      <link name='wrist_1_link'>
        <pose frame=''>1.1843 -0.950959 1.1273 3.14159 -0 3.14159</pose>
        <inertial>
          <pose frame=''>0 0 0 0 -0 0</pose>
          <mass>1.96</mass>
          <inertia>
            <ixx>0.00510825</ixx>
            <ixy>0</ixy>
            <ixz>0</ixz>
            <iyy>0.00510825</iyy>
            <iyz>0</iyz>
            <izz>0.0055125</izz>
          </inertia>
        </inertial>
        <collision name='wrist_1_link_collision'>
          <pose frame=''>0 0 0 0 -0 0</pose>
          <geometry>
            <mesh>
              <scale>1 1 1</scale>
              <uri>/home/gizem/catkin_ws/src/fmauch_universal_robot/ur_description/meshes/ur10/collision/wrist1.stl</uri>
            </mesh>
          </geometry>
          <max_contacts>10</max_contacts>
          <surface>
            <contact>
              <ode/>
            </contact>
            <bounce/>
            <friction>
              <torsional>
                <ode/>
              </torsional>
              <ode/>
            </friction>
          </surface>
        </collision>
        <visual name='wrist_1_link_visual'>
          <pose frame=''>0 0 0 0 -0 0</pose>
          <geometry>
            <mesh>
              <scale>1 1 1</scale>
              <uri>/home/gizem/catkin_ws/src/fmauch_universal_robot/ur_description/meshes/ur10/visual/wrist1.dae</uri>
            </mesh>
          </geometry>
        </visual>
        <self_collide>0</self_collide>
        <enable_wind>0</enable_wind>
        <kinematic>0</kinematic>
      </link>
      <joint name='wrist_1_joint' type='revolute'>
        <child>wrist_1_link</child>
        <parent>forearm_link</parent>
        <axis>
          <xyz>0 1 0</xyz>
          <limit>
            <lower>-3.14159</lower>
            <upper>3.14159</upper>
            <effort>54</effort>
            <velocity>3.2</velocity>
          </limit>
          <dynamics>
            <damping>0</damping>
            <friction>0</friction>
            <spring_reference>0</spring_reference>
            <spring_stiffness>0</spring_stiffness>
          </dynamics>
          <use_parent_model_frame>1</use_parent_model_frame>
        </axis>
      </joint>
      <link name='wrist_2_link'>
        <pose frame=''>1.1843 -0.836059 1.1273 3.14159 -0 3.14159</pose>
        <inertial>
          <pose frame=''>0 0 0 0 -0 0</pose>
          <mass>1.96</mass>
          <inertia>
            <ixx>0.00510825</ixx>
            <ixy>0</ixy>
            <ixz>0</ixz>
            <iyy>0.00510825</iyy>
            <iyz>0</iyz>
            <izz>0.0055125</izz>
          </inertia>
        </inertial>
        <collision name='wrist_2_link_collision'>
          <pose frame=''>0 0 0 0 -0 0</pose>
          <geometry>
            <mesh>
              <scale>1 1 1</scale>
              <uri>/home/gizem/catkin_ws/src/fmauch_universal_robot/ur_description/meshes/ur10/collision/wrist2.stl</uri>
            </mesh>
          </geometry>
          <max_contacts>10</max_contacts>
          <surface>
            <contact>
              <ode/>
            </contact>
            <bounce/>
            <friction>
              <torsional>
                <ode/>
              </torsional>
              <ode/>
            </friction>
          </surface>
        </collision>
        <visual name='wrist_2_link_visual'>
          <pose frame=''>0 0 0 0 -0 0</pose>
          <geometry>
            <mesh>
              <scale>1 1 1</scale>
              <uri>/home/gizem/catkin_ws/src/fmauch_universal_robot/ur_description/meshes/ur10/visual/wrist2.dae</uri>
            </mesh>
          </geometry>
        </visual>
        <self_collide>0</self_collide>
        <enable_wind>0</enable_wind>
        <kinematic>0</kinematic>
      </link>
      <joint name='wrist_2_joint' type='revolute'>
        <child>wrist_2_link</child>
        <parent>wrist_1_link</parent>
        <axis>
          <xyz>0 0 -1</xyz>
          <limit>
            <lower>-3.14159</lower>
            <upper>3.14159</upper>
            <effort>54</effort>
            <velocity>3.2</velocity>
          </limit>
          <dynamics>
            <damping>0</damping>
            <friction>0</friction>
            <spring_reference>0</spring_reference>
            <spring_stiffness>0</spring_stiffness>
          </dynamics>
          <use_parent_model_frame>1</use_parent_model_frame>
        </axis>
      </joint>
      <link name='wrist_3_link'>
        <pose frame=''>1.1843 -0.836059 1.0116 3.14159 -0 3.14159</pose>
        <inertial>
          <pose frame=''>0.000252 0.072377 0.002863 0 -0 0</pose>
          <mass>0.379715</mass>
          <inertia>
            <ixx>0.00312102</ixx>
            <ixy>-9.3841e-06</ixy>
            <ixz>2.03179e-06</ixz>
            <iyy>0.000751809</iyy>
            <iyz>-7.87144e-05</iyz>
            <izz>0.00323075</izz>
          </inertia>
        </inertial>
        <collision name='wrist_3_link_collision'>
          <pose frame=''>0 0 0 0 -0 0</pose>
          <geometry>
            <mesh>
              <scale>1 1 1</scale>
              <uri>/home/gizem/catkin_ws/src/fmauch_universal_robot/ur_description/meshes/ur10/collision/wrist3.stl</uri>
            </mesh>
          </geometry>
          <max_contacts>10</max_contacts>
          <surface>
            <contact>
              <ode/>
            </contact>
            <bounce/>
            <friction>
              <torsional>
                <ode/>
              </torsional>
              <ode/>
            </friction>
          </surface>
        </collision>
        <collision name='wrist_3_link_fixed_joint_lump__ee_link_collision_1'>
          <pose frame=''>-0 0.0822 0 0 -0 1.5708</pose>
          <geometry>
            <box>
              <size>0.01 0.01 0.01</size>
            </box>
          </geometry>
          <max_contacts>10</max_contacts>
          <surface>
            <contact>
              <ode/>
            </contact>
            <bounce/>
            <friction>
              <torsional>
                <ode/>
              </torsional>
              <ode/>
            </friction>
          </surface>
        </collision>
        <collision name='wrist_3_link_fixed_joint_lump__H1_base_link_collision_2'>
          <pose frame=''>0 0.1037 0 -1.5708 -0 -0</pose>
          <geometry>
            <mesh>
              <scale>1 1 1</scale>
              <uri>/home/gizem/catkin_ws/src/fh_desc/meshes/v2/palm_link_simple.dae</uri>
            </mesh>
          </geometry>
          <surface>
            <contact>
              <ode>
                <kp>1e+06</kp>
                <kd>100</kd>
                <max_vel>1</max_vel>
                <min_depth>0.002</min_depth>
              </ode>
            </contact>
            <friction>
              <ode>
                <mu>1.5</mu>
                <mu2>1.5</mu2>
                <fdir1>1 0 0</fdir1>
              </ode>
              <torsional>
                <ode/>
              </torsional>
            </friction>
            <bounce/>
          </surface>
          <max_contacts>10</max_contacts>
        </collision>
        <visual name='wrist_3_link_visual'>
          <pose frame=''>0 0 0 0 -0 0</pose>
          <geometry>
            <mesh>
              <scale>1 1 1</scale>
              <uri>/home/gizem/catkin_ws/src/fmauch_universal_robot/ur_description/meshes/ur10/visual/wrist3.dae</uri>
            </mesh>
          </geometry>
        </visual>
        <visual name='wrist_3_link_fixed_joint_lump__H1_base_link_visual_1'>
          <pose frame=''>0 0.1037 0 -1.5708 -0 -0</pose>
          <geometry>
            <mesh>
              <scale>1 1 1</scale>
              <uri>/home/gizem/catkin_ws/src/fh_desc/meshes/v2/palm_link_simple.dae</uri>
            </mesh>
          </geometry>
          <material>
            <script>
              <name>Gazebo/DarkGrey</name>
              <uri>file://media/materials/scripts/gazebo.material</uri>
            </script>
          </material>
        </visual>
        <visual name='wrist_3_link_fixed_joint_lump__H1_F1_palm_link_visual_2'>
          <pose frame=''>-0.045 0.1037 0.025981 1.5708 0.785393 3.14159</pose>
          <geometry>
            <mesh>
              <scale>1 1 1</scale>
              <uri>/home/gizem/catkin_ws/src/fh_desc/meshes/v2/finger_palm_link.dae</uri>
            </mesh>
          </geometry>
          <material>
            <script>
              <name>Gazebo/DarkGrey</name>
              <uri>file://media/materials/scripts/gazebo.material</uri>
            </script>
          </material>
        </visual>
        <visual name='wrist_3_link_fixed_joint_lump__H1_F2_palm_link_visual_3'>
          <pose frame=''>0 0.1037 -0.029019 -1.5708 -0 -0</pose>
          <geometry>
            <mesh>
              <scale>1 1 1</scale>
              <uri>/home/gizem/catkin_ws/src/fh_desc/meshes/v2/finger_palm_link.dae</uri>
            </mesh>
          </geometry>
          <material>
            <script>
              <name>Gazebo/DarkGrey</name>
              <uri>file://media/materials/scripts/gazebo.material</uri>
            </script>
          </material>
        </visual>
        <visual name='wrist_3_link_fixed_joint_lump__H1_F3_palm_link_visual_4'>
          <pose frame=''>0.045 0.1037 0.025981 1.5708 -0.785393 3.14159</pose>
          <geometry>
            <mesh>
              <scale>1 1 1</scale>
              <uri>/home/gizem/catkin_ws/src/fh_desc/meshes/v2/finger_palm_link.dae</uri>
            </mesh>
          </geometry>
          <material>
            <script>
              <name>Gazebo/DarkGrey</name>
              <uri>file://media/materials/scripts/gazebo.material</uri>
            </script>
          </material>
        </visual>
        <velocity_decay/>
        <velocity_decay/>
        <velocity_decay/>
        <gravity>1</gravity>
        <velocity_decay/>
        <self_collide>0</self_collide>
        <enable_wind>0</enable_wind>
        <kinematic>0</kinematic>
      </link>
      <joint name='wrist_3_joint' type='revolute'>
        <child>wrist_3_link</child>
        <parent>wrist_2_link</parent>
        <axis>
          <xyz>0 1 0</xyz>
          <limit>
            <lower>-3.14159</lower>
            <upper>3.14159</upper>
            <effort>54</effort>
            <velocity>3.2</velocity>
          </limit>
          <dynamics>
            <damping>0</damping>
            <friction>0</friction>
            <spring_reference>0</spring_reference>
            <spring_stiffness>0</spring_stiffness>
          </dynamics>
          <use_parent_model_frame>1</use_parent_model_frame>
        </axis>
      </joint>
      <link name='H1_F1_base_link'>
        <pose frame=''>1.2293 -0.732194 0.985619 -1.5708 -0.762991 0</pose>
        <inertial>
          <pose frame=''>-0.000143 0.026569 0.053875 0 -0 0</pose>
          <mass>0.174652</mass>
          <inertia>
            <ixx>0.000298373</ixx>
            <ixy>-5.05752e-07</ixy>
            <ixz>1.94983e-07</ixz>
            <iyy>0.00029963</iyy>
            <iyz>2.79565e-05</iyz>
            <izz>0.00013489</izz>
          </inertia>
        </inertial>
        <collision name='H1_F1_base_link_collision'>
          <pose frame=''>0 0 0 0 -0 0</pose>
          <geometry>
            <mesh>
              <scale>1 1 1</scale>
              <uri>/home/gizem/catkin_ws/src/fh_desc/meshes/v2/finger_base_link_simple.dae</uri>
            </mesh>
          </geometry>
          <surface>
            <contact>
              <ode>
                <kp>1e+06</kp>
                <kd>100</kd>
                <max_vel>1</max_vel>
                <min_depth>0.002</min_depth>
              </ode>
            </contact>
            <friction>
              <ode>
                <mu>1.5</mu>
                <mu2>1.5</mu2>
                <fdir1>1 0 0</fdir1>
              </ode>
              <torsional>
                <ode/>
              </torsional>
            </friction>
            <bounce/>
          </surface>
          <max_contacts>10</max_contacts>
        </collision>
        <visual name='H1_F1_base_link_visual'>
          <pose frame=''>0 0 0 0 -0 0</pose>
          <geometry>
            <mesh>
              <scale>1 1 1</scale>
              <uri>/home/gizem/catkin_ws/src/fh_desc/meshes/v2/finger_base_link_simple.dae</uri>
            </mesh>
          </geometry>
          <material>
            <script>
              <name>Gazebo/DarkGrey</name>
              <uri>file://media/materials/scripts/gazebo.material</uri>
            </script>
          </material>
        </visual>
        <gravity>1</gravity>
        <velocity_decay/>
        <self_collide>0</self_collide>
        <enable_wind>0</enable_wind>
        <kinematic>0</kinematic>
      </link>
      <joint name='H1_F1J1' type='revolute'>
        <child>H1_F1_base_link</child>
        <parent>wrist_3_link</parent>
        <axis>
          <xyz>-0 1 0</xyz>
          <limit>
            <lower>-0.785398</lower>
            <upper>0.785398</upper>
            <effort>50</effort>
            <velocity>1</velocity>
          </limit>
          <dynamics>
            <damping>0</damping>
            <friction>0</friction>
            <spring_reference>0</spring_reference>
            <spring_stiffness>0</spring_stiffness>
          </dynamics>
          <use_parent_model_frame>1</use_parent_model_frame>
        </axis>
        <physics>
          <ode>
            <implicit_spring_damper>1</implicit_spring_damper>
            <cfm_damping>1</cfm_damping>
            <limit>
              <cfm>0</cfm>
              <erp>0.2</erp>
            </limit>
          </ode>
        </physics>
      </joint>
      <link name='H1_F1_link_1'>
        <pose frame=''>1.25349 -0.615364 0.960322 -1.5001 -0.762991 0</pose>
        <inertial>
          <pose frame=''>-0.000142 -0.001354 0.027761 0 -0 0</pose>
          <mass>0.082776</mass>
          <inertia>
            <ixx>4.6107e-05</ixx>
            <ixy>7.47741e-08</ixy>
            <ixz>-2.25165e-07</ixz>
            <iyy>5.27678e-05</iyy>
            <iyz>-3.64603e-07</iyz>
            <izz>2.896e-05</izz>
          </inertia>
        </inertial>
        <collision name='H1_F1_link_1_collision'>
          <pose frame=''>0 0 0 0 -0 0</pose>
          <geometry>
            <mesh>
              <scale>1 1 1</scale>
              <uri>/home/gizem/catkin_ws/src/fh_desc/meshes/v2/finger_prox_link_simple.dae</uri>
            </mesh>
          </geometry>
          <surface>
            <contact>
              <ode>
                <kp>1e+06</kp>
                <kd>100</kd>
                <max_vel>1</max_vel>
                <min_depth>0.002</min_depth>
              </ode>
            </contact>
            <friction>
              <ode>
                <mu>1.5</mu>
                <mu2>1.5</mu2>
                <fdir1>1 0 0</fdir1>
              </ode>
              <torsional>
                <ode/>
              </torsional>
            </friction>
            <bounce/>
          </surface>
          <max_contacts>10</max_contacts>
        </collision>
        <visual name='H1_F1_link_1_visual'>
          <pose frame=''>0 0 0 0 -0 0</pose>
          <geometry>
            <mesh>
              <scale>1 1 1</scale>
              <uri>/home/gizem/catkin_ws/src/fh_desc/meshes/v2/finger_prox_link_simple.dae</uri>
            </mesh>
          </geometry>
          <material>
            <script>
              <name>Gazebo/DarkGrey</name>
              <uri>file://media/materials/scripts/gazebo.material</uri>
            </script>
          </material>
        </visual>
        <gravity>1</gravity>
        <velocity_decay/>
        <self_collide>0</self_collide>
        <enable_wind>0</enable_wind>
        <kinematic>0</kinematic>
      </link>
      <joint name='H1_F1J2' type='revolute'>
        <child>H1_F1_link_1</child>
        <parent>H1_F1_base_link</parent>
        <axis>
          <xyz>0.722772 0 0.691086</xyz>
          <limit>
            <lower>-1.39626</lower>
            <upper>1.0472</upper>
            <effort>50</effort>
            <velocity>1</velocity>
          </limit>
          <dynamics>
            <damping>0</damping>
            <friction>0</friction>
            <spring_reference>0</spring_reference>
            <spring_stiffness>0</spring_stiffness>
          </dynamics>
          <use_parent_model_frame>1</use_parent_model_frame>
        </axis>
        <physics>
          <ode>
            <implicit_spring_damper>1</implicit_spring_damper>
            <cfm_damping>1</cfm_damping>
            <limit>
              <cfm>0</cfm>
              <erp>0.2</erp>
            </limit>
          </ode>
        </physics>
      </joint>
      <link name='H1_F1_link_2'>
        <pose frame=''>1.25056 -0.555514 0.963385 -1.50697 -0.762991 0</pose>
        <inertial>
          <pose frame=''>0.000147 -0.001929 0.020669 0 -0 0</pose>
          <mass>0.0360682</mass>
          <inertia>
            <ixx>1.45995e-05</ixx>
            <ixy>-5.02031e-08</ixy>
            <ixz>-1.65836e-07</ixz>
            <iyy>1.46464e-05</iyy>
            <iyz>-2.25421e-07</iyz>
            <izz>4.03881e-06</izz>
          </inertia>
        </inertial>
        <collision name='H1_F1_link_2_collision'>
          <pose frame=''>0 0 0 0 -0 0</pose>
          <geometry>
            <mesh>
              <scale>1 1 1</scale>
              <uri>/home/gizem/catkin_ws/src/fh_desc/meshes/v2/finger_dist_link_simple.dae</uri>
            </mesh>
          </geometry>
          <surface>
            <contact>
              <ode>
                <kp>1e+06</kp>
                <kd>100</kd>
                <max_vel>1</max_vel>
                <min_depth>0.002</min_depth>
              </ode>
            </contact>
            <friction>
              <ode>
                <mu>1.5</mu>
                <mu2>1.5</mu2>
                <fdir1>1 0 0</fdir1>
              </ode>
              <torsional>
                <ode/>
              </torsional>
            </friction>
            <bounce/>
          </surface>
          <max_contacts>10</max_contacts>
        </collision>
        <collision name='H1_F1_link_2_fixed_joint_lump__H1_F1_tip_collision_1'>
          <pose frame=''>0 0 0 0 -0 0</pose>
          <geometry>
            <mesh>
              <scale>1 1 1</scale>
              <uri>/home/gizem/catkin_ws/src/fh_desc/meshes/omd-d18-tip.dae</uri>
            </mesh>
          </geometry>
          <surface>
            <contact>
              <ode>
                <kp>1e+06</kp>
                <kd>100</kd>
                <max_vel>1</max_vel>
                <min_depth>0.002</min_depth>
              </ode>
            </contact>
            <friction>
              <ode>
                <mu>1.5</mu>
                <mu2>1.5</mu2>
                <fdir1>1 0 0</fdir1>
              </ode>
              <torsional>
                <ode/>
              </torsional>
            </friction>
            <bounce/>
          </surface>
          <max_contacts>10</max_contacts>
        </collision>
        <visual name='H1_F1_link_2_visual'>
          <pose frame=''>0 0 0 0 -0 0</pose>
          <geometry>
            <mesh>
              <scale>1 1 1</scale>
              <uri>/home/gizem/catkin_ws/src/fh_desc/meshes/v2/finger_dist_link_simple.dae</uri>
            </mesh>
          </geometry>
          <material>
            <script>
              <name>Gazebo/DarkGrey</name>
              <uri>file://media/materials/scripts/gazebo.material</uri>
            </script>
          </material>
        </visual>
        <visual name='H1_F1_link_2_fixed_joint_lump__H1_F1_tip_visual_1'>
          <pose frame=''>0 0 0 0 -0 0</pose>
          <geometry>
            <mesh>
              <scale>1 1 1</scale>
              <uri>/home/gizem/catkin_ws/src/fh_desc/meshes/omd-d18-tip.dae</uri>
            </mesh>
          </geometry>
          <material>
            <script>
              <name>Gazebo/DarkGrey</name>
              <uri>file://media/materials/scripts/gazebo.material</uri>
            </script>
          </material>
        </visual>
        <velocity_decay/>
        <gravity>1</gravity>
        <velocity_decay/>
        <self_collide>0</self_collide>
        <enable_wind>0</enable_wind>
        <kinematic>0</kinematic>
      </link>
      <joint name='H1_F1J3' type='revolute'>
        <child>H1_F1_link_2</child>
        <parent>H1_F1_link_1</parent>
        <axis>
          <xyz>0.722772 0 0.691086</xyz>
          <limit>
            <lower>-1.0472</lower>
            <upper>1.5708</upper>
            <effort>50</effort>
            <velocity>1</velocity>
          </limit>
          <dynamics>
            <damping>0</damping>
            <friction>0</friction>
            <spring_reference>0</spring_reference>
            <spring_stiffness>0</spring_stiffness>
          </dynamics>
          <use_parent_model_frame>1</use_parent_model_frame>
        </axis>
        <physics>
          <ode>
            <implicit_spring_damper>1</implicit_spring_damper>
            <cfm_damping>1</cfm_damping>
            <limit>
              <cfm>0</cfm>
              <erp>0.2</erp>
            </limit>
          </ode>
        </physics>
      </joint>
      <link name='H1_F2_base_link'>
        <pose frame=''>1.1843 -0.732194 1.04062 1.5708 -0.022402 -3.14159</pose>
        <inertial>
          <pose frame=''>-0.000143 0.026569 0.053875 0 -0 0</pose>
          <mass>0.174652</mass>
          <inertia>
            <ixx>0.000298373</ixx>
            <ixy>-5.05752e-07</ixy>
            <ixz>1.94983e-07</ixz>
            <iyy>0.00029963</iyy>
            <iyz>2.79565e-05</iyz>
            <izz>0.00013489</izz>
          </inertia>
        </inertial>
        <collision name='H1_F2_base_link_collision'>
          <pose frame=''>0 0 0 0 -0 0</pose>
          <geometry>
            <mesh>
              <scale>1 1 1</scale>
              <uri>/home/gizem/catkin_ws/src/fh_desc/meshes/v2/finger_base_link_simple.dae</uri>
            </mesh>
          </geometry>
          <surface>
            <contact>
              <ode>
                <kp>1e+06</kp>
                <kd>100</kd>
                <max_vel>1</max_vel>
                <min_depth>0.002</min_depth>
              </ode>
            </contact>
            <friction>
              <ode>
                <mu>1.5</mu>
                <mu2>1.5</mu2>
                <fdir1>1 0 0</fdir1>
              </ode>
              <torsional>
                <ode/>
              </torsional>
            </friction>
            <bounce/>
          </surface>
          <max_contacts>10</max_contacts>
        </collision>
        <visual name='H1_F2_base_link_visual'>
          <pose frame=''>0 0 0 0 -0 0</pose>
          <geometry>
            <mesh>
              <scale>1 1 1</scale>
              <uri>/home/gizem/catkin_ws/src/fh_desc/meshes/v2/finger_base_link_simple.dae</uri>
            </mesh>
          </geometry>
          <material>
            <script>
              <name>Gazebo/DarkGrey</name>
              <uri>file://media/materials/scripts/gazebo.material</uri>
            </script>
          </material>
        </visual>
        <gravity>1</gravity>
        <velocity_decay/>
        <self_collide>0</self_collide>
        <enable_wind>0</enable_wind>
        <kinematic>0</kinematic>
      </link>
      <joint name='H1_F2J1' type='revolute'>
        <child>H1_F2_base_link</child>
        <parent>wrist_3_link</parent>
        <axis>
          <xyz>-0 1 0</xyz>
          <limit>
            <lower>-0.785398</lower>
            <upper>0.785398</upper>
            <effort>30</effort>
            <velocity>1</velocity>
          </limit>
          <dynamics>
            <damping>0</damping>
            <friction>0</friction>
            <spring_reference>0</spring_reference>
            <spring_stiffness>0</spring_stiffness>
          </dynamics>
          <use_parent_model_frame>1</use_parent_model_frame>
        </axis>
        <physics>
          <ode>
            <implicit_spring_damper>1</implicit_spring_damper>
            <cfm_damping>1</cfm_damping>
            <limit>
              <cfm>0</cfm>
              <erp>0.2</erp>
            </limit>
          </ode>
        </physics>
      </joint>
      <link name='H1_F2_link_1'>
        <pose frame=''>1.18508 -0.615364 1.07561 1.64149 -0.022402 -3.14159</pose>
        <inertial>
          <pose frame=''>-0.000142 -0.001354 0.027761 0 -0 0</pose>
          <mass>0.082776</mass>
          <inertia>
            <ixx>4.6107e-05</ixx>
            <ixy>7.47741e-08</ixy>
            <ixz>-2.25165e-07</ixz>
            <iyy>5.27678e-05</iyy>
            <iyz>-3.64603e-07</iyz>
            <izz>2.896e-05</izz>
          </inertia>
        </inertial>
        <collision name='H1_F2_link_1_collision'>
          <pose frame=''>0 0 0 0 -0 0</pose>
          <geometry>
            <mesh>
              <scale>1 1 1</scale>
              <uri>/home/gizem/catkin_ws/src/fh_desc/meshes/v2/finger_prox_link_simple.dae</uri>
            </mesh>
          </geometry>
          <surface>
            <contact>
              <ode>
                <kp>1e+06</kp>
                <kd>100</kd>
                <max_vel>1</max_vel>
                <min_depth>0.002</min_depth>
              </ode>
            </contact>
            <friction>
              <ode>
                <mu>1.5</mu>
                <mu2>1.5</mu2>
                <fdir1>1 0 0</fdir1>
              </ode>
              <torsional>
                <ode/>
              </torsional>
            </friction>
            <bounce/>
          </surface>
          <max_contacts>10</max_contacts>
        </collision>
        <visual name='H1_F2_link_1_visual'>
          <pose frame=''>0 0 0 0 -0 0</pose>
          <geometry>
            <mesh>
              <scale>1 1 1</scale>
              <uri>/home/gizem/catkin_ws/src/fh_desc/meshes/v2/finger_prox_link_simple.dae</uri>
            </mesh>
          </geometry>
          <material>
            <script>
              <name>Gazebo/DarkGrey</name>
              <uri>file://media/materials/scripts/gazebo.material</uri>
            </script>
          </material>
        </visual>
        <gravity>1</gravity>
        <velocity_decay/>
        <self_collide>0</self_collide>
        <enable_wind>0</enable_wind>
        <kinematic>0</kinematic>
      </link>
      <joint name='H1_F2J2' type='revolute'>
        <child>H1_F2_link_1</child>
        <parent>H1_F2_base_link</parent>
        <axis>
          <xyz>-0.999749 -0 0.0224</xyz>
          <limit>
            <lower>-1.39626</lower>
            <upper>1.0472</upper>
            <effort>30</effort>
            <velocity>1</velocity>
          </limit>
          <dynamics>
            <damping>0</damping>
            <friction>0</friction>
            <spring_reference>0</spring_reference>
            <spring_stiffness>0</spring_stiffness>
          </dynamics>
          <use_parent_model_frame>1</use_parent_model_frame>
        </axis>
        <physics>
          <ode>
            <implicit_spring_damper>1</implicit_spring_damper>
            <cfm_damping>1</cfm_damping>
            <limit>
              <cfm>0</cfm>
              <erp>0.2</erp>
            </limit>
          </ode>
        </physics>
      </joint>
      <link name='H1_F2_link_2'>
        <pose frame=''>1.18499 -0.555514 1.07137 1.63463 -0.022402 -3.14159</pose>
        <inertial>
          <pose frame=''>0.000147 -0.001929 0.020669 0 -0 0</pose>
          <mass>0.0360682</mass>
          <inertia>
            <ixx>1.45995e-05</ixx>
            <ixy>-5.02031e-08</ixy>
            <ixz>-1.65836e-07</ixz>
            <iyy>1.46464e-05</iyy>
            <iyz>-2.25421e-07</iyz>
            <izz>4.03881e-06</izz>
          </inertia>
        </inertial>
        <collision name='H1_F2_link_2_collision'>
          <pose frame=''>0 0 0 0 -0 0</pose>
          <geometry>
            <mesh>
              <scale>1 1 1</scale>
              <uri>/home/gizem/catkin_ws/src/fh_desc/meshes/v2/finger_dist_link_simple.dae</uri>
            </mesh>
          </geometry>
          <surface>
            <contact>
              <ode>
                <kp>1e+06</kp>
                <kd>100</kd>
                <max_vel>1</max_vel>
                <min_depth>0.002</min_depth>
              </ode>
            </contact>
            <friction>
              <ode>
                <mu>1.5</mu>
                <mu2>1.5</mu2>
                <fdir1>1 0 0</fdir1>
              </ode>
              <torsional>
                <ode/>
              </torsional>
            </friction>
            <bounce/>
          </surface>
          <max_contacts>10</max_contacts>
        </collision>
        <collision name='H1_F2_link_2_fixed_joint_lump__H1_F2_tip_collision_1'>
          <pose frame=''>0 0 0 0 -0 0</pose>
          <geometry>
            <mesh>
              <scale>1 1 1</scale>
              <uri>/home/gizem/catkin_ws/src/fh_desc/meshes/omd-d18-tip.dae</uri>
            </mesh>
          </geometry>
          <surface>
            <contact>
              <ode>
                <kp>1e+06</kp>
                <kd>100</kd>
                <max_vel>1</max_vel>
                <min_depth>0.002</min_depth>
              </ode>
            </contact>
            <friction>
              <ode>
                <mu>1.5</mu>
                <mu2>1.5</mu2>
                <fdir1>1 0 0</fdir1>
              </ode>
              <torsional>
                <ode/>
              </torsional>
            </friction>
            <bounce/>
          </surface>
          <max_contacts>10</max_contacts>
        </collision>
        <visual name='H1_F2_link_2_visual'>
          <pose frame=''>0 0 0 0 -0 0</pose>
          <geometry>
            <mesh>
              <scale>1 1 1</scale>
              <uri>/home/gizem/catkin_ws/src/fh_desc/meshes/v2/finger_dist_link_simple.dae</uri>
            </mesh>
          </geometry>
          <material>
            <script>
              <name>Gazebo/DarkGrey</name>
              <uri>file://media/materials/scripts/gazebo.material</uri>
            </script>
          </material>
        </visual>
        <visual name='H1_F2_link_2_fixed_joint_lump__H1_F2_tip_visual_1'>
          <pose frame=''>0 0 0 0 -0 0</pose>
          <geometry>
            <mesh>
              <scale>1 1 1</scale>
              <uri>/home/gizem/catkin_ws/src/fh_desc/meshes/omd-d18-tip.dae</uri>
            </mesh>
          </geometry>
          <material>
            <script>
              <name>Gazebo/DarkGrey</name>
              <uri>file://media/materials/scripts/gazebo.material</uri>
            </script>
          </material>
        </visual>
        <velocity_decay/>
        <gravity>1</gravity>
        <velocity_decay/>
        <self_collide>0</self_collide>
        <enable_wind>0</enable_wind>
        <kinematic>0</kinematic>
      </link>
      <joint name='H1_F2J3' type='revolute'>
        <child>H1_F2_link_2</child>
        <parent>H1_F2_link_1</parent>
        <axis>
          <xyz>-0.999749 -0 0.0224</xyz>
          <limit>
            <lower>-1.0472</lower>
            <upper>1.5708</upper>
            <effort>30</effort>
            <velocity>1</velocity>
          </limit>
          <dynamics>
            <damping>0</damping>
            <friction>0</friction>
            <spring_reference>0</spring_reference>
            <spring_stiffness>0</spring_stiffness>
          </dynamics>
          <use_parent_model_frame>1</use_parent_model_frame>
        </axis>
        <physics>
          <ode>
            <implicit_spring_damper>1</implicit_spring_damper>
            <cfm_damping>1</cfm_damping>
            <limit>
              <cfm>0</cfm>
              <erp>0.2</erp>
            </limit>
          </ode>
        </physics>
      </joint>
      <link name='H1_F3_base_link'>
        <pose frame=''>1.1393 -0.732194 0.985619 -1.5708 0.807795 0</pose>
        <inertial>
          <pose frame=''>-0.000143 0.026569 0.053875 0 -0 0</pose>
          <mass>0.174652</mass>
          <inertia>
            <ixx>0.000298373</ixx>
            <ixy>-5.05752e-07</ixy>
            <ixz>1.94983e-07</ixz>
            <iyy>0.00029963</iyy>
            <iyz>2.79565e-05</iyz>
            <izz>0.00013489</izz>
          </inertia>
        </inertial>
        <collision name='H1_F3_base_link_collision'>
          <pose frame=''>0 0 0 0 -0 0</pose>
          <geometry>
            <mesh>
              <scale>1 1 1</scale>
              <uri>/home/gizem/catkin_ws/src/fh_desc/meshes/v2/finger_base_link_simple.dae</uri>
            </mesh>
          </geometry>
          <surface>
            <contact>
              <ode>
                <kp>1e+06</kp>
                <kd>100</kd>
                <max_vel>1</max_vel>
                <min_depth>0.002</min_depth>
              </ode>
            </contact>
            <friction>
              <ode>
                <mu>1.5</mu>
                <mu2>1.5</mu2>
                <fdir1>1 0 0</fdir1>
              </ode>
              <torsional>
                <ode/>
              </torsional>
            </friction>
            <bounce/>
          </surface>
          <max_contacts>10</max_contacts>
        </collision>
        <visual name='H1_F3_base_link_visual'>
          <pose frame=''>0 0 0 0 -0 0</pose>
          <geometry>
            <mesh>
              <scale>1 1 1</scale>
              <uri>/home/gizem/catkin_ws/src/fh_desc/meshes/v2/finger_base_link_simple.dae</uri>
            </mesh>
          </geometry>
          <material>
            <script>
              <name>Gazebo/DarkGrey</name>
              <uri>file://media/materials/scripts/gazebo.material</uri>
            </script>
          </material>
        </visual>
        <gravity>1</gravity>
        <velocity_decay/>
        <self_collide>0</self_collide>
        <enable_wind>0</enable_wind>
        <kinematic>0</kinematic>
      </link>
      <joint name='H1_F3J1' type='revolute'>
        <child>H1_F3_base_link</child>
        <parent>wrist_3_link</parent>
        <axis>
          <xyz>-0 1 0</xyz>
          <limit>
            <lower>-0.785398</lower>
            <upper>0.785398</upper>
            <effort>30</effort>
            <velocity>1</velocity>
          </limit>
          <dynamics>
            <damping>0</damping>
            <friction>0</friction>
            <spring_reference>0</spring_reference>
            <spring_stiffness>0</spring_stiffness>
          </dynamics>
          <use_parent_model_frame>1</use_parent_model_frame>
        </axis>
        <physics>
          <ode>
            <implicit_spring_damper>1</implicit_spring_damper>
            <cfm_damping>1</cfm_damping>
            <limit>
              <cfm>0</cfm>
              <erp>0.2</erp>
            </limit>
          </ode>
        </physics>
      </joint>
      <link name='H1_F3_link_1'>
        <pose frame=''>1.114 -0.615364 0.961431 -1.5001 0.807795 -0</pose>
        <inertial>
          <pose frame=''>-0.000142 -0.001354 0.027761 0 -0 0</pose>
          <mass>0.082776</mass>
          <inertia>
            <ixx>4.6107e-05</ixx>
            <ixy>7.47741e-08</ixy>
            <ixz>-2.25165e-07</ixz>
            <iyy>5.27678e-05</iyy>
            <iyz>-3.64603e-07</iyz>
            <izz>2.896e-05</izz>
          </inertia>
        </inertial>
        <collision name='H1_F3_link_1_collision'>
          <pose frame=''>0 0 0 0 -0 0</pose>
          <geometry>
            <mesh>
              <scale>1 1 1</scale>
              <uri>/home/gizem/catkin_ws/src/fh_desc/meshes/v2/finger_prox_link_simple.dae</uri>
            </mesh>
          </geometry>
          <surface>
            <contact>
              <ode>
                <kp>1e+06</kp>
                <kd>100</kd>
                <max_vel>1</max_vel>
                <min_depth>0.002</min_depth>
              </ode>
            </contact>
            <friction>
              <ode>
                <mu>1.5</mu>
                <mu2>1.5</mu2>
                <fdir1>1 0 0</fdir1>
              </ode>
              <torsional>
                <ode/>
              </torsional>
            </friction>
            <bounce/>
          </surface>
          <max_contacts>10</max_contacts>
        </collision>
        <visual name='H1_F3_link_1_visual'>
          <pose frame=''>0 0 0 0 -0 0</pose>
          <geometry>
            <mesh>
              <scale>1 1 1</scale>
              <uri>/home/gizem/catkin_ws/src/fh_desc/meshes/v2/finger_prox_link_simple.dae</uri>
            </mesh>
          </geometry>
          <material>
            <script>
              <name>Gazebo/DarkGrey</name>
              <uri>file://media/materials/scripts/gazebo.material</uri>
            </script>
          </material>
        </visual>
        <gravity>1</gravity>
        <velocity_decay/>
        <self_collide>0</self_collide>
        <enable_wind>0</enable_wind>
        <kinematic>0</kinematic>
      </link>
      <joint name='H1_F3J2' type='revolute'>
        <child>H1_F3_link_1</child>
        <parent>H1_F3_base_link</parent>
        <axis>
          <xyz>0.691094 0 -0.722765</xyz>
          <limit>
            <lower>-1.39626</lower>
            <upper>1.0472</upper>
            <effort>30</effort>
            <velocity>1</velocity>
          </limit>
          <dynamics>
            <damping>0</damping>
            <friction>0</friction>
            <spring_reference>0</spring_reference>
            <spring_stiffness>0</spring_stiffness>
          </dynamics>
          <use_parent_model_frame>1</use_parent_model_frame>
        </axis>
        <physics>
          <ode>
            <implicit_spring_damper>1</implicit_spring_damper>
            <cfm_damping>1</cfm_damping>
            <limit>
              <cfm>0</cfm>
              <erp>0.2</erp>
            </limit>
          </ode>
        </physics>
      </joint>
      <link name='H1_F3_link_2'>
        <pose frame=''>1.11707 -0.555514 0.96436 -1.50697 0.807795 -0</pose>
        <inertial>
          <pose frame=''>0.000147 -0.001929 0.020669 0 -0 0</pose>
          <mass>0.0360682</mass>
          <inertia>
            <ixx>1.45995e-05</ixx>
            <ixy>-5.02031e-08</ixy>
            <ixz>-1.65836e-07</ixz>
            <iyy>1.46464e-05</iyy>
            <iyz>-2.25421e-07</iyz>
            <izz>4.03881e-06</izz>
          </inertia>
        </inertial>
        <collision name='H1_F3_link_2_collision'>
          <pose frame=''>0 0 0 0 -0 0</pose>
          <geometry>
            <mesh>
              <scale>1 1 1</scale>
              <uri>/home/gizem/catkin_ws/src/fh_desc/meshes/v2/finger_dist_link_simple.dae</uri>
            </mesh>
          </geometry>
          <surface>
            <contact>
              <ode>
                <kp>1e+06</kp>
                <kd>100</kd>
                <max_vel>1</max_vel>
                <min_depth>0.002</min_depth>
              </ode>
            </contact>
            <friction>
              <ode>
                <mu>1.5</mu>
                <mu2>1.5</mu2>
                <fdir1>1 0 0</fdir1>
              </ode>
              <torsional>
                <ode/>
              </torsional>
            </friction>
            <bounce/>
          </surface>
          <max_contacts>10</max_contacts>
        </collision>
        <collision name='H1_F3_link_2_fixed_joint_lump__H1_F3_tip_collision_1'>
          <pose frame=''>0 0 0 0 -0 0</pose>
          <geometry>
            <mesh>
              <scale>1 1 1</scale>
              <uri>/home/gizem/catkin_ws/src/fh_desc/meshes/omd-d18-tip.dae</uri>
            </mesh>
          </geometry>
          <surface>
            <contact>
              <ode>
                <kp>1e+06</kp>
                <kd>100</kd>
                <max_vel>1</max_vel>
                <min_depth>0.002</min_depth>
              </ode>
            </contact>
            <friction>
              <ode>
                <mu>1.5</mu>
                <mu2>1.5</mu2>
                <fdir1>1 0 0</fdir1>
              </ode>
              <torsional>
                <ode/>
              </torsional>
            </friction>
            <bounce/>
          </surface>
          <max_contacts>10</max_contacts>
        </collision>
        <visual name='H1_F3_link_2_visual'>
          <pose frame=''>0 0 0 0 -0 0</pose>
          <geometry>
            <mesh>
              <scale>1 1 1</scale>
              <uri>/home/gizem/catkin_ws/src/fh_desc/meshes/v2/finger_dist_link_simple.dae</uri>
            </mesh>
          </geometry>
          <material>
            <script>
              <name>Gazebo/DarkGrey</name>
              <uri>file://media/materials/scripts/gazebo.material</uri>
            </script>
          </material>
        </visual>
        <visual name='H1_F3_link_2_fixed_joint_lump__H1_F3_tip_visual_1'>
          <pose frame=''>0 0 0 0 -0 0</pose>
          <geometry>
            <mesh>
              <scale>1 1 1</scale>
              <uri>/home/gizem/catkin_ws/src/fh_desc/meshes/omd-d18-tip.dae</uri>
            </mesh>
          </geometry>
          <material>
            <script>
              <name>Gazebo/DarkGrey</name>
              <uri>file://media/materials/scripts/gazebo.material</uri>
            </script>
          </material>
        </visual>
        <velocity_decay/>
        <gravity>1</gravity>
        <velocity_decay/>
        <self_collide>0</self_collide>
        <enable_wind>0</enable_wind>
        <kinematic>0</kinematic>
      </link>
      <joint name='H1_F3J3' type='revolute'>
        <child>H1_F3_link_2</child>
        <parent>H1_F3_link_1</parent>
        <axis>
          <xyz>0.691094 0 -0.722765</xyz>
          <limit>
            <lower>-1.0472</lower>
            <upper>1.5708</upper>
            <effort>30</effort>
            <velocity>1</velocity>
          </limit>
          <dynamics>
            <damping>0</damping>
            <friction>0</friction>
            <spring_reference>0</spring_reference>
            <spring_stiffness>0</spring_stiffness>
          </dynamics>
          <use_parent_model_frame>1</use_parent_model_frame>
        </axis>
        <physics>
          <ode>
            <implicit_spring_damper>1</implicit_spring_damper>
            <cfm_damping>1</cfm_damping>
            <limit>
              <cfm>0</cfm>
              <erp>0.2</erp>
            </limit>
          </ode>
        </physics>
      </joint>
      <plugin name='ros_control' filename='libgazebo_ros_control.so'>
        <robotSimType>gazebo_ros_control/DefaultRobotHWSim</robotSimType>
        <robotNamespace>/</robotNamespace>
      </plugin>
      <static>0</static>
      <plugin name='imu_controller' filename='libgazebo_ros_imu.so'>
        <alwaysOn>1</alwaysOn>
        <updateRate>50</updateRate>
        <topicName>imu/data</topicName>
        <serviceName>imu/is_calibrated</serviceName>
        <gaussianNoise>2.89e-08</gaussianNoise>
        <xyzOffsets>0 0 0</xyzOffsets>
        <rpyOffsets>0 0 0</rpyOffsets>
        <robotNamespace>/</robotNamespace>
        <bodyName>wrist_3_link</bodyName>
        <xyzOffset>-0.0005 -0.0802 -2.44824e-15</xyzOffset>
        <rpyOffset>1.73538e-18 -0.0274156 -1.54338</rpyOffset>
      </plugin>
      <pose frame=''>0 0 0 0 -0 0</pose>
    </model>
    <model name='ground_plane'>
      <static>1</static>
      <link name='link'>
        <collision name='collision'>
          <geometry>
            <plane>
              <normal>0 0 1</normal>
              <size>100 100</size>
            </plane>
          </geometry>
          <surface>
            <contact>
              <collide_bitmask>65535</collide_bitmask>
              <ode/>
            </contact>
            <friction>
              <ode>
                <mu>100</mu>
                <mu2>50</mu2>
              </ode>
              <torsional>
                <ode/>
              </torsional>
            </friction>
            <bounce/>
          </surface>
          <max_contacts>10</max_contacts>
        </collision>
        <visual name='visual'>
          <cast_shadows>0</cast_shadows>
          <geometry>
            <plane>
              <normal>0 0 1</normal>
              <size>100 100</size>
            </plane>
          </geometry>
          <material>
            <script>
              <uri>file://media/materials/scripts/gazebo.material</uri>
              <name>Gazebo/Grey</name>
            </script>
          </material>
        </visual>
        <self_collide>0</self_collide>
        <enable_wind>0</enable_wind>
        <kinematic>0</kinematic>
      </link>
      <pose frame=''>0.343524 0.647311 0 0 -0 0</pose>
    </model>
    <light name='user_directional_light_2' type='directional'>
      <pose frame=''>0.731132 -0.890069 1 0 -0 0</pose>
      <diffuse>0.5 0.5 0.5 1</diffuse>
      <specular>0.1 0.1 0.1 1</specular>
      <direction>0.1 0.1 -0.9</direction>
      <attenuation>
        <range>20</range>
        <constant>0.5</constant>
        <linear>0.01</linear>
        <quadratic>0.001</quadratic>
      </attenuation>
      <cast_shadows>1</cast_shadows>
    </light>
    <model name='coke_can'>
      <link name='link'>
        <inertial>
          <pose frame=''>0 0 0.06 0 -0 0</pose>
          <mass>0.39</mass>
          <inertia>
            <ixx>0.00055575</ixx>
            <ixy>0</ixy>
            <ixz>0</ixz>
            <iyy>0.00055575</iyy>
            <iyz>0</iyz>
            <izz>0.0001755</izz>
          </inertia>
        </inertial>
        <collision name='collision'>
          <pose frame=''>0.003937 0.004724 -0.18 0 -0 0</pose>
          <geometry>
            <mesh>
              <uri>model://coke_can/meshes/coke_can.dae</uri>
            </mesh>
          </geometry>
          <surface>
            <friction>
              <ode>
                <mu>1</mu>
                <mu2>1</mu2>
              </ode>
              <torsional>
                <ode/>
              </torsional>
            </friction>
            <contact>
              <ode>
                <kp>1e+07</kp>
                <kd>1</kd>
                <min_depth>0.001</min_depth>
                <max_vel>0.1</max_vel>
              </ode>
            </contact>
            <bounce/>
          </surface>
          <max_contacts>10</max_contacts>
        </collision>
        <visual name='visual'>
          <pose frame=''>0.003937 0.004724 -0.18 0 -0 0</pose>
          <geometry>
            <mesh>
              <uri>model://coke_can/meshes/coke_can.dae</uri>
            </mesh>
          </geometry>
        </visual>
        <self_collide>0</self_collide>
        <enable_wind>0</enable_wind>
        <kinematic>0</kinematic>
      </link>
      <pose frame=''>1.0889 1.76222 0 0 -0 0</pose>
    </model>
  </world>
</sdf>
